Workbook

Sheet Logboek
A1: Pagina | B1: Datum | C1: Omschrijving | D1: Type | E1: Schets | F1: Log | G1: Patroon | H1: Gedicht
A2: 0 | B2: 1 | C2: Kaft | D2: Schets | E2: =COUNTIF($D$2:$D2,E$1) -> 1 | F2: =COUNTIF($D$2:$D2,F$1) -> 0 | G2: =COUNTIF($D$2:$D2,G$1) -> 0 | H2: =COUNTIF($D$2:$D2,H$1) -> 0
A3: 1 | B3: 1 | D3: Log | E3: =COUNTIF($D$2:$D3,E$1) -> 1 | F3: =COUNTIF($D$2:$D3,F$1) -> 1 | G3: =COUNTIF($D$2:$D3,G$1) -> 0 | H3: =COUNTIF($D$2:$D3,H$1) -> 0
A4: 2 | B4: 2 | D4: Log | E4: =COUNTIF($D$2:$D4,E$1) -> 1 | F4: =COUNTIF($D$2:$D4,F$1) -> 2 | G4: =COUNTIF($D$2:$D4,G$1) -> 0 | H4: =COUNTIF($D$2:$D4,H$1) -> 0
A5: 3 | B5: 3 | D5: Log | E5: =COUNTIF($D$2:$D5,E$1) -> 1 | F5: =COUNTIF($D$2:$D5,F$1) -> 3 | G5: =COUNTIF($D$2:$D5,G$1) -> 0 | H5: =COUNTIF($D$2:$D5,H$1) -> 0
A6: 4 | B6: 5 | C6: Zonnebloem | D6: Patroon | E6: =COUNTIF($D$2:$D6,E$1) -> 1 | F6: =COUNTIF($D$2:$D6,F$1) -> 3 | G6: =COUNTIF($D$2:$D6,G$1) -> 1 | H6: =COUNTIF($D$2:$D6,H$1) -> 0
A7: 5 | B7: 6 | D7: Log | E7: =COUNTIF($D$2:$D7,E$1) -> 1 | F7: =COUNTIF($D$2:$D7,F$1) -> 4 | G7: =COUNTIF($D$2:$D7,G$1) -> 1 | H7: =COUNTIF($D$2:$D7,H$1) -> 0
A8: 6 | B8: 8 | D8: Log | E8: =COUNTIF($D$2:$D8,E$1) -> 1 | F8: =COUNTIF($D$2:$D8,F$1) -> 5 | G8: =COUNTIF($D$2:$D8,G$1) -> 1 | H8: =COUNTIF($D$2:$D8,H$1) -> 0
A9: 7 | B9: 11 | D9: Log | E9: =COUNTIF($D$2:$D9,E$1) -> 1 | F9: =COUNTIF($D$2:$D9,F$1) -> 6 | G9: =COUNTIF($D$2:$D9,G$1) -> 1 | H9: =COUNTIF($D$2:$D9,H$1) -> 0
A10: 8 | B10: 13 | D10: Log | E10: =COUNTIF($D$2:$D10,E$1) -> 1 | F10: =COUNTIF($D$2:$D10,F$1) -> 7 | G10: =COUNTIF($D$2:$D10,G$1) -> 1 | H10: =COUNTIF($D$2:$D10,H$1) -> 0
A11: 9 | B11: 13 | C11: Koperen ei | D11: Schets | E11: =COUNTIF($D$2:$D11,E$1) -> 2 | F11: =COUNTIF($D$2:$D11,F$1) -> 7 | G11: =COUNTIF($D$2:$D11,G$1) -> 1 | H11: =COUNTIF($D$2:$D11,H$1) -> 0
A12: 10 | B12: 14 | D12: Log | E12: =COUNTIF($D$2:$D12,E$1) -> 2 | F12: =COUNTIF($D$2:$D12,F$1) -> 8 | G12: =COUNTIF($D$2:$D12,G$1) -> 1 | H12: =COUNTIF($D$2:$D12,H$1) -> 0
A13: 11 | B13: 18 | D13: Log | E13: =COUNTIF($D$2:$D13,E$1) -> 2 | F13: =COUNTIF($D$2:$D13,F$1) -> 9 | G13: =COUNTIF($D$2:$D13,G$1) -> 1 | H13: =COUNTIF($D$2:$D13,H$1) -> 0
A14: 12 | B14: 19 | C14: Ruitje | D14: Patroon | E14: =COUNTIF($D$2:$D14,E$1) -> 2 | F14: =COUNTIF($D$2:$D14,F$1) -> 9 | G14: =COUNTIF($D$2:$D14,G$1) -> 2 | H14: =COUNTIF($D$2:$D14,H$1) -> 0
A15: 13 | B15: 20 | D15: Log | E15: =COUNTIF($D$2:$D15,E$1) -> 2 | F15: =COUNTIF($D$2:$D15,F$1) -> 10 | G15: =COUNTIF($D$2:$D15,G$1) -> 2 | H15: =COUNTIF($D$2:$D15,H$1) -> 0
A16: 14 | B16: 21 | D16: Log | E16: =COUNTIF($D$2:$D16,E$1) -> 2 | F16: =COUNTIF($D$2:$D16,F$1) -> 11 | G16: =COUNTIF($D$2:$D16,G$1) -> 2 | H16: =COUNTIF($D$2:$D16,H$1) -> 0
A17: 15 | B17: 23 | D17: Log | E17: =COUNTIF($D$2:$D17,E$1) -> 2 | F17: =COUNTIF($D$2:$D17,F$1) -> 12 | G17: =COUNTIF($D$2:$D17,G$1) -> 2 | H17: =COUNTIF($D$2:$D17,H$1) -> 0
A18: 16 | B18: 24 | D18: Log | E18: =COUNTIF($D$2:$D18,E$1) -> 2 | F18: =COUNTIF($D$2:$D18,F$1) -> 13 | G18: =COUNTIF($D$2:$D18,G$1) -> 2 | H18: =COUNTIF($D$2:$D18,H$1) -> 0
A19: 17 | B19: 26 | D19: Log | E19: =COUNTIF($D$2:$D19,E$1) -> 2 | F19: =COUNTIF($D$2:$D19,F$1) -> 14 | G19: =COUNTIF($D$2:$D19,G$1) -> 2 | H19: =COUNTIF($D$2:$D19,H$1) -> 0
A20: 18 | B20: 27 | C20: Pimpelmees | D20: Schets | E20: =COUNTIF($D$2:$D20,E$1) -> 3 | F20: =COUNTIF($D$2:$D20,F$1) -> 14 | G20: =COUNTIF($D$2:$D20,G$1) -> 2 | H20: =COUNTIF($D$2:$D20,H$1) -> 0
A21: 19 | B21: 27 | D21: Log | E21: =COUNTIF($D$2:$D21,E$1) -> 3 | F21: =COUNTIF($D$2:$D21,F$1) -> 15 | G21: =COUNTIF($D$2:$D21,G$1) -> 2 | H21: =COUNTIF($D$2:$D21,H$1) -> 0
A22: 20 | B22: 29 | C22: Mijnvogel in Mineur | D22: Gedicht | E22: =COUNTIF($D$2:$D22,E$1) -> 3 | F22: =COUNTIF($D$2:$D22,F$1) -> 15 | G22: =COUNTIF($D$2:$D22,G$1) -> 2 | H22: =COUNTIF($D$2:$D22,H$1) -> 1
A23: 21 | B23: 30 | D23: Log | E23: =COUNTIF($D$2:$D23,E$1) -> 3 | F23: =COUNTIF($D$2:$D23,F$1) -> 16 | G23: =COUNTIF($D$2:$D23,G$1) -> 2 | H23: =COUNTIF($D$2:$D23,H$1) -> 1
A24: 22 | B24: 31 | C24: Vlinderbeest | D24: Schets | E24: =COUNTIF($D$2:$D24,E$1) -> 4 | F24: =COUNTIF($D$2:$D24,F$1) -> 16 | G24: =COUNTIF($D$2:$D24,G$1) -> 2 | H24: =COUNTIF($D$2:$D24,H$1) -> 1
A25: 23 | B25: 31 | D25: Log | E25: =COUNTIF($D$2:$D25,E$1) -> 4 | F25: =COUNTIF($D$2:$D25,F$1) -> 17 | G25: =COUNTIF($D$2:$D25,G$1) -> 2 | H25: =COUNTIF($D$2:$D25,H$1) -> 1
A26: 24 | B26: 32 | D26: Log | E26: =COUNTIF($D$2:$D26,E$1) -> 4 | F26: =COUNTIF($D$2:$D26,F$1) -> 18 | G26: =COUNTIF($D$2:$D26,G$1) -> 2 | H26: =COUNTIF($D$2:$D26,H$1) -> 1
A27: 25 | B27: 33 | D27: Log | E27: =COUNTIF($D$2:$D27,E$1) -> 4 | F27: =COUNTIF($D$2:$D27,F$1) -> 19 | G27: =COUNTIF($D$2:$D27,G$1) -> 2 | H27: =COUNTIF($D$2:$D27,H$1) -> 1 | J27: Log | K27: =COUNTIF($D$1:$D$121,$J27) -> 46 | L27: =$K27/$K$31 -> 0.58227848
A28: 26 | B28: 34 | D28: Log | E28: =COUNTIF($D$2:$D28,E$1) -> 4 | F28: =COUNTIF($D$2:$D28,F$1) -> 20 | G28: =COUNTIF($D$2:$D28,G$1) -> 2 | H28: =COUNTIF($D$2:$D28,H$1) -> 1 | J28: Schets | K28: =COUNTIF($D$1:$D$121,$J28) -> 17 | L28: =$K28/$K$31 -> 0.21518987
A29: 27 | B29: =ROUND((B30+B28)/2,0) -> 36 | C29: Scheepswiel | D29: Patroon | E29: =COUNTIF($D$2:$D29,E$1) -> 4 | F29: =COUNTIF($D$2:$D29,F$1) -> 20 | G29: =COUNTIF($D$2:$D29,G$1) -> 3 | H29: =COUNTIF($D$2:$D29,H$1) -> 1 | J29: Patroon | K29: =COUNTIF($D$1:$D$121,$J29) -> 11 | L29: =$K29/$K$31 -> 0.13924051
A30: 28 | B30: =ROUND((B32+B28)/2,0) -> 37 | C30: Vondst | D30: Schets | E30: =COUNTIF($D$2:$D30,E$1) -> 5 | F30: =COUNTIF($D$2:$D30,F$1) -> 20 | G30: =COUNTIF($D$2:$D30,G$1) -> 3 | H30: =COUNTIF($D$2:$D30,H$1) -> 1 | J30: Gedicht | K30: =COUNTIF($D$1:$D$121,$J30) -> 4 | L30: =$K30/$K$31 -> 0.050632911
A31: 29 | B31: =ROUND((B32+B30)/2,0) -> 38 | C31: Tala | D31: Schets | E31: =COUNTIF($D$2:$D31,E$1) -> 6 | F31: =COUNTIF($D$2:$D31,F$1) -> 20 | G31: =COUNTIF($D$2:$D31,G$1) -> 3 | H31: =COUNTIF($D$2:$D31,H$1) -> 1 | J31: TOTAL | K31: =COUNTA($D$1:$D$121) -> 79 | L31: =$K31/$K$31 -> 1
A32: 30 | B32: 39 | D32: Log | E32: =COUNTIF($D$2:$D32,E$1) -> 6 | F32: =COUNTIF($D$2:$D32,F$1) -> 21 | G32: =COUNTIF($D$2:$D32,G$1) -> 3 | H32: =COUNTIF($D$2:$D32,H$1) -> 1
A33: 31 | B33: 42 | D33: Log | E33: =COUNTIF($D$2:$D33,E$1) -> 6 | F33: =COUNTIF($D$2:$D33,F$1) -> 22 | G33: =COUNTIF($D$2:$D33,G$1) -> 3 | H33: =COUNTIF($D$2:$D33,H$1) -> 1
A34: 32 | B34: =ROUND((B35+B33)/2,0) -> 45 | C34: Vlinder | D34: Patroon | E34: =COUNTIF($D$2:$D34,E$1) -> 6 | F34: =COUNTIF($D$2:$D34,F$1) -> 22 | G34: =COUNTIF($D$2:$D34,G$1) -> 4 | H34: =COUNTIF($D$2:$D34,H$1) -> 1
A35: 33 | B35: 48 | D35: Log | E35: =COUNTIF($D$2:$D35,E$1) -> 6 | F35: =COUNTIF($D$2:$D35,F$1) -> 23 | G35: =COUNTIF($D$2:$D35,G$1) -> 4 | H35: =COUNTIF($D$2:$D35,H$1) -> 1
A36: 34 | B36: 58 | D36: Log | E36: =COUNTIF($D$2:$D36,E$1) -> 6 | F36: =COUNTIF($D$2:$D36,F$1) -> 24 | G36: =COUNTIF($D$2:$D36,G$1) -> 4 | H36: =COUNTIF($D$2:$D36,H$1) -> 1
A37: 35 | B37: =ROUND((B38+B36)/2,0) -> 60 | C37: Wolkendroom | D37: Schets | E37: =COUNTIF($D$2:$D37,E$1) -> 7 | F37: =COUNTIF($D$2:$D37,F$1) -> 24 | G37: =COUNTIF($D$2:$D37,G$1) -> 4 | H37: =COUNTIF($D$2:$D37,H$1) -> 1
A38: 36 | B38: 62 | D38: Log | E38: =COUNTIF($D$2:$D38,E$1) -> 7 | F38: =COUNTIF($D$2:$D38,F$1) -> 25 | G38: =COUNTIF($D$2:$D38,G$1) -> 4 | H38: =COUNTIF($D$2:$D38,H$1) -> 1
A39: 37 | B39: 62 | C39: Kanarie | D39: Gedicht | E39: =COUNTIF($D$2:$D39,E$1) -> 7 | F39: =COUNTIF($D$2:$D39,F$1) -> 25 | G39: =COUNTIF($D$2:$D39,G$1) -> 4 | H39: =COUNTIF($D$2:$D39,H$1) -> 2
A40: 38 | B40: 63 | D40: Log | E40: =COUNTIF($D$2:$D40,E$1) -> 7 | F40: =COUNTIF($D$2:$D40,F$1) -> 26 | G40: =COUNTIF($D$2:$D40,G$1) -> 4 | H40: =COUNTIF($D$2:$D40,H$1) -> 2
...

Sheet Ongevallen
A1: Jaar | B1: Dag | C1: Leeftijd | E1: Omschrijving
A2: 429 | B2: 153 | C2: =ROUNDDOWN(IF(A2>0,D2-(415+(270/365)),""),0) -> 13 | D2: =A2+(153/365) -> 429.41918 | E2: Stage
A3: 429 | B3: 268 | C3: =ROUNDDOWN(IF(A3>0,D3-(415+(270/365)),""),0) -> 13 | D3: =A3+(153/365) -> 429.41918 | E3: Touw vernieling
A4: 432 | B4: 352 | C4: =ROUNDDOWN(IF(A4>0,D4-(415+(270/365)),""),0) -> 16 | D4: =A4+(153/365) -> 432.41918 | E4: Instorting
A5: 433 | B5: 201 | C5: =ROUNDDOWN(IF(A5>0,D5-(415+(270/365)),""),0) -> 17 | D5: =A5+(153/365) -> 433.41918 | E5: Mijnmuil
A6: 436 | B6: 67 | C6: =ROUNDDOWN(IF(A6>0,D6-(415+(270/365)),""),0) -> 20 | D6: =A6+(153/365) -> 436.41918 | E6: Gevallen krat
A7: 436 | B7: 199 | C7: =ROUNDDOWN(IF(A7>0,D7-(415+(270/365)),""),0) -> 20 | D7: =A7+(153/365) -> 436.41918 | E7: Interventie
A8: 437 | B8: 153 | C8: =ROUNDDOWN(IF(A8>0,D8-(415+(270/365)),""),0) -> 21 | D8: =A8+(153/365) -> 437.41918 | E8: Appelboom
A9: 439 | B9: 241 | C9: =ROUNDDOWN(IF(A9>0,D9-(415+(270/365)),""),0) -> 23 | D9: =A9+(153/365) -> 439.41918 | E9: Explosie
A10: 440 | B10: 93 | C10: =ROUNDDOWN(IF(A10>0,D10-(415+(270/365)),""),0) -> 24 | D10: =A10+(153/365) -> 440.41918 | E10: Gaslek
A11: 443 | B11: 302 | C11: =ROUNDDOWN(IF(A11>0,D11-(415+(270/365)),""),0) -> 27 | D11: =A11+(153/365) -> 443.41918 | E11: De Val
A12: 446 | B12: 212 | C12: =ROUNDDOWN(IF(A12>0,D12-(415+(270/365)),""),0) -> 30 | D12: =A12+(153/365) -> 446.41918 | E12: Overbelast
A13: 447 | B13: 112 | C13: =ROUNDDOWN(IF(A13>0,D13-(415+(270/365)),""),0) -> 31 | D13: =A13+(153/365) -> 447.41918 | E13: Ondervoeding
... A19: 450 | B19: 81 | C19: =ROUNDDOWN(IF(A19>0,D19-(415+(270/365)),""),0) -> 34 | D19: =A19+(153/365) -> 450.41918 | E19: Overval

Sheet Tatjes
A1: Model | B1: Kleur1 | C1: Kleur2 | D1: #Model | E1: #Kleur1 | F1: #Kleur2
A2: Bloem | B2: Blauw | C2: Geel | D2: =IF(ISBLANK(A2),"",COUNTIF(A:A,A2)) -> 16 | E2: =IF(ISBLANK(B2),"",COUNTIF(B:B,B2)) -> 10 | F2: =IF(ISBLANK(C2),"",COUNTIF(C:C,C2)) -> 18
A3: Bloem | B3: Blauw | C3: Aqua | D3: =IF(ISBLANK(A3),"",COUNTIF(A:A,A3)) -> 16 | E3: =IF(ISBLANK(B3),"",COUNTIF(B:B,B3)) -> 10 | F3: =IF(ISBLANK(C3),"",COUNTIF(C:C,C3)) -> 11
A4: Bloem | B4: Blauw | C4: Marine | D4: =IF(ISBLANK(A4),"",COUNTIF(A:A,A4)) -> 16 | E4: =IF(ISBLANK(B4),"",COUNTIF(B:B,B4)) -> 10 | F4: =IF(ISBLANK(C4),"",COUNTIF(C:C,C4)) -> 3
A5: Bloem | B5: Zilver | C5: Paars | D5: =IF(ISBLANK(A5),"",COUNTIF(A:A,A5)) -> 16 | E5: =IF(ISBLANK(B5),"",COUNTIF(B:B,B5)) -> 9 | F5: =IF(ISBLANK(C5),"",COUNTIF(C:C,C5)) -> 8
A6: Bloem | B6: Zilver | C6: Paars | D6: =IF(ISBLANK(A6),"",COUNTIF(A:A,A6)) -> 16 | E6: =IF(ISBLANK(B6),"",COUNTIF(B:B,B6)) -> 9 | F6: =IF(ISBLANK(C6),"",COUNTIF(C:C,C6)) -> 8
A7: Bloem | B7: Zilver | C7: Marine | D7: =IF(ISBLANK(A7),"",COUNTIF(A:A,A7)) -> 16 | E7: =IF(ISBLANK(B7),"",COUNTIF(B:B,B7)) -> 9 | F7: =IF(ISBLANK(C7),"",COUNTIF(C:C,C7)) -> 3
A8: Bloem | B8: Lila | C8: Lichtgeel | D8: =IF(ISBLANK(A8),"",COUNTIF(A:A,A8)) -> 16 | E8: =IF(ISBLANK(B8),"",COUNTIF(B:B,B8)) -> 7 | F8: =IF(ISBLANK(C8),"",COUNTIF(C:C,C8)) -> 4
A9: Bloem | B9: Lila | C9: Roze | D9: =IF(ISBLANK(A9),"",COUNTIF(A:A,A9)) -> 16 | E9: =IF(ISBLANK(B9),"",COUNTIF(B:B,B9)) -> 7 | F9: =IF(ISBLANK(C9),"",COUNTIF(C:C,C9)) -> 4
A10: Bloem | B10: Paars | C10: Roze | D10: =IF(ISBLANK(A10),"",COUNTIF(A:A,A10)) -> 16 | E10: =IF(ISBLANK(B10),"",COUNTIF(B:B,B10)) -> 7 | F10: =IF(ISBLANK(C10),"",COUNTIF(C:C,C10)) -> 4
A11: Bloem | B11: Zwart | C11: Zilver | D11: =IF(ISBLANK(A11),"",COUNTIF(A:A,A11)) -> 16 | E11: =IF(ISBLANK(B11),"",COUNTIF(B:B,B11)) -> 7 | F11: =IF(ISBLANK(C11),"",COUNTIF(C:C,C11)) -> 3
A12: Bloem | B12: Fuchsia | C12: Geel | D12: =IF(ISBLANK(A12),"",COUNTIF(A:A,A12)) -> 16 | E12: =IF(ISBLANK(B12),"",COUNTIF(B:B,B12)) -> 5 | F12: =IF(ISBLANK(C12),"",COUNTIF(C:C,C12)) -> 18
A13: Bloem | B13: Fuchsia | C13: Roze | D13: =IF(ISBLANK(A13),"",COUNTIF(A:A,A13)) -> 16 | E13: =IF(ISBLANK(B13),"",COUNTIF(B:B,B13)) -> 5 | F13: =IF(ISBLANK(C13),"",COUNTIF(C:C,C13)) -> 4
... A32: Libel | B32: Aqua | C32: Lichtgeel | D32: =IF(ISBLANK(A32),"",COUNTIF(A:A,A32)) -> 15 | E32: =IF(ISBLANK(B32),"",COUNTIF(B:B,B32)) -> 2 | F32: =IF(ISBLANK(C32),"",COUNTIF(C:C,C32)) -> 4
A33: Klaver4 | B33: Geel | D33: =IF(ISBLANK(A33),"",COUNTIF(A:A,A33)) -> 12 | E33: =IF(ISBLANK(B33),"",COUNTIF(B:B,B33)) -> 9 | F33: =IF(ISBLANK(C33),"",COUNTIF(C:C,C33))
A34: Klaver4 | B34: Geel | D34: =IF(ISBLANK(A34),"",COUNTIF(A:A,A34)) -> 12 | E34: =IF(ISBLANK(B34),"",COUNTIF(B:B,B34)) -> 9 | F34: =IF(ISBLANK(C34),"",COUNTIF(C:C,C34))
A35: Klaver4 | B35: Geel | D35: =IF(ISBLANK(A35),"",COUNTIF(A:A,A35)) -> 12 | E35: =IF(ISBLANK(B35),"",COUNTIF(B:B,B35)) -> 9 | F35: =IF(ISBLANK(C35),"",COUNTIF(C:C,C35))
A36: Klaver4 | B36: Geel | D36: =IF(ISBLANK(A36),"",COUNTIF(A:A,A36)) -> 12 | E36: =IF(ISBLANK(B36),"",COUNTIF(B:B,B36)) -> 9 | F36: =IF(ISBLANK(C36),"",COUNTIF(C:C,C36))
A37: Klaver4 | B37: Groen | D37: =IF(ISBLANK(A37),"",COUNTIF(A:A,A37)) -> 12 | E37: =IF(ISBLANK(B37),"",COUNTIF(B:B,B37)) -> 8 | F37: =IF(ISBLANK(C37),"",COUNTIF(C:C,C37))
A38: Klaver4 | B38: Gras | D38: =IF(ISBLANK(A38),"",COUNTIF(A:A,A38)) -> 12 | E38: =IF(ISBLANK(B38),"",COUNTIF(B:B,B38)) -> 7 | F38: =IF(ISBLANK(C38),"",COUNTIF(C:C,C38))
A39: Klaver4 | B39: Gras | D39: =IF(ISBLANK(A39),"",COUNTIF(A:A,A39)) -> 12 | E39: =IF(ISBLANK(B39),"",COUNTIF(B:B,B39)) -> 7 | F39: =IF(ISBLANK(C39),"",COUNTIF(C:C,C39))
A40: Klaver4 | B40: Lichtgeel | D40: =IF(ISBLANK(A40),"",COUNTIF(A:A,A40)) -> 12 | E40: =IF(ISBLANK(B40),"",COUNTIF(B:B,B40)) -> 5 | F40: =IF(ISBLANK(C40),"",COUNTIF(C:C,C40))
A41: Klaver4 | B41: Lichtgeel | D41: =IF(ISBLANK(A41),"",COUNTIF(A:A,A41)) -> 12 | E41: =IF(ISBLANK(B41),"",COUNTIF(B:B,B41)) -> 5 | F41: =IF(ISBLANK(C41),"",COUNTIF(C:C,C41))
A42: Klaver4 | B42: Lichtgeel | D42: =IF(ISBLANK(A42),"",COUNTIF(A:A,A42)) -> 12 | E42: =IF(ISBLANK(B42),"",COUNTIF(B:B,B42)) -> 5 | F42: =IF(ISBLANK(C42),"",COUNTIF(C:C,C42))
A43: Klaver4 | B43: Olijf | D43: =IF(ISBLANK(A43),"",COUNTIF(A:A,A43)) -> 12 | E43: =IF(ISBLANK(B43),"",COUNTIF(B:B,B43)) -> 2 | F43: =IF(ISBLANK(C43),"",COUNTIF(C:C,C43))
A44: Klaver4 | B44: Olijf | D44: =IF(ISBLANK(A44),"",COUNTIF(A:A,A44)) -> 12 | E44: =IF(ISBLANK(B44),"",COUNTIF(B:B,B44)) -> 2 | F44: =IF(ISBLANK(C44),"",COUNTIF(C:C,C44))
A45: Vlinder | B45: Blauw | C45: Aqua | D45: =IF(ISBLANK(A45),"",COUNTIF(A:A,A45)) -> 11 | E45: =IF(ISBLANK(B45),"",COUNTIF(B:B,B45)) -> 10 | F45: =IF(ISBLANK(C45),"",COUNTIF(C:C,C45)) -> 11
A46: Vlinder | B46: Blauw | C46: Aqua | D46: =IF(ISBLANK(A46),"",COUNTIF(A:A,A46)) -> 11 | E46: =IF(ISBLANK(B46),"",COUNTIF(B:B,B46)) -> 10 | F46: =IF(ISBLANK(C46),"",COUNTIF(C:C,C46)) -> 11
A47: Vlinder | B47: Blauw | C47: Gras | D47: =IF(ISBLANK(A47),"",COUNTIF(A:A,A47)) -> 11 | E47: =IF(ISBLANK(B47),"",COUNTIF(B:B,B47)) -> 10 | F47: =IF(ISBLANK(C47),"",COUNTIF(C:C,C47)) -> 3
A48: Vlinder | B48: Geel | C48: Oranje | D48: =IF(ISBLANK(A48),"",COUNTIF(A:A,A48)) -> 11 | E48: =IF(ISBLANK(B48),"",COUNTIF(B:B,B48)) -> 9 | F48: =IF(ISBLANK(C48),"",COUNTIF(C:C,C48)) -> 1
A49: Vlinder | B49: Gras | C49: Blauw | D49: =IF(ISBLANK(A49),"",COUNTIF(A:A,A49)) -> 11 | E49: =IF(ISBLANK(B49),"",COUNTIF(B:B,B49)) -> 7 | F49: =IF(ISBLANK(C49),"",COUNTIF(C:C,C49)) -> 6
A50: Vlinder | B50: Gras | C50: Blauw | D50: =IF(ISBLANK(A50),"",COUNTIF(A:A,A50)) -> 11 | E50: =IF(ISBLANK(B50),"",COUNTIF(B:B,B50)) -> 7 | F50: =IF(ISBLANK(C50),"",COUNTIF(C:C,C50)) -> 6
A51: Vlinder | B51: Lila | C51: Aqua | D51: =IF(ISBLANK(A51),"",COUNTIF(A:A,A51)) -> 11 | E51: =IF(ISBLANK(B51),"",COUNTIF(B:B,B51)) -> 7 | F51: =IF(ISBLANK(C51),"",COUNTIF(C:C,C51)) -> 11
A52: Vlinder | B52: Lila | C52: Paars | D52: =IF(ISBLANK(A52),"",COUNTIF(A:A,A52)) -> 11 | E52: =IF(ISBLANK(B52),"",COUNTIF(B:B,B52)) -> 7 | F52: =IF(ISBLANK(C52),"",COUNTIF(C:C,C52)) -> 8
A53: Vlinder | B53: Paars | C53: Fuchsia | D53: =IF(ISBLANK(A53),"",COUNTIF(A:A,A53)) -> 11 | E53: =IF(ISBLANK(B53),"",COUNTIF(B:B,B53)) -> 7 | F53: =IF(ISBLANK(C53),"",COUNTIF(C:C,C53)) -> 3
A54: Vlinder | B54: Oranje | C54: Geel | D54: =IF(ISBLANK(A54),"",COUNTIF(A:A,A54)) -> 11 | E54: =IF(ISBLANK(B54),"",COUNTIF(B:B,B54)) -> 5 | F54: =IF(ISBLANK(C54),"",COUNTIF(C:C,C54)) -> 18
A55: Vlinder | B55: Rood | C55: Geel | D55: =IF(ISBLANK(A55),"",COUNTIF(A:A,A55)) -> 11 | E55: =IF(ISBLANK(B55),"",COUNTIF(B:B,B55)) -> 2 | F55: =IF(ISBLANK(C55),"",COUNTIF(C:C,C55)) -> 18
A56: Ruit | B56: Zilver | C56: Paars | D56: =IF(ISBLANK(A56),"",COUNTIF(A:A,A56)) -> 10 | E56: =IF(ISBLANK(B56),"",COUNTIF(B:B,B56)) -> 9 | F56: =IF(ISBLANK(C56),"",COUNTIF(C:C,C56)) -> 8
... A77: Blad | B77: Roest | C77: Geel | D77: =IF(ISBLANK(A77),"",COUNTIF(A:A,A77)) -> 6 | E77: =IF(ISBLANK(B77),"",COUNTIF(B:B,B77)) -> 1 | F77: =IF(ISBLANK(C77),"",COUNTIF(C:C,C77)) -> 18
A78: Klaver3 | B78: Geel | D78: =IF(ISBLANK(A78),"",COUNTIF(A:A,A78)) -> 4 | E78: =IF(ISBLANK(B78),"",COUNTIF(B:B,B78)) -> 9 | F78: =IF(ISBLANK(C78),"",COUNTIF(C:C,C78))
...

Sheet Tatdata
A1: Model | B1: # | D1: Kleur1 | E1: # | G1: Kleur2 | H1: # | J1: Kleur | K1: #
A2: Bloem | B2: =COUNTIF(Tatjes!A:A,A2) -> 16 | D2: Blauw | E2: =COUNTIF(Tatjes!B:B,D2) -> 10 | G2: Geel | H2: =COUNTIF(Tatjes!C:C,G2) -> 18 | J2: Geel | K2: =COUNTIF(Tatjes!B:B,J2)*2+COUNTIF(Tatjes!C:C,J2) -> 36
A3: Libel | B3: =COUNTIF(Tatjes!A:A,A3) -> 15 | D3: Geel | E3: =COUNTIF(Tatjes!B:B,D3) -> 9 | G3: Aqua | H3: =COUNTIF(Tatjes!C:C,G3) -> 11 | J3: Blauw | K3: =COUNTIF(Tatjes!B:B,J3)*2+COUNTIF(Tatjes!C:C,J3) -> 26
A4: Klaver4 | B4: =COUNTIF(Tatjes!A:A,A4) -> 12 | D4: Zilver | E4: =COUNTIF(Tatjes!B:B,D4) -> 9 | G4: Paars | H4: =COUNTIF(Tatjes!C:C,G4) -> 8 | J4: Paars | K4: =COUNTIF(Tatjes!B:B,J4)*2+COUNTIF(Tatjes!C:C,J4) -> 22
A5: Vlinder | B5: =COUNTIF(Tatjes!A:A,A5) -> 11 | D5: Groen | E5: =COUNTIF(Tatjes!B:B,D5) -> 8 | G5: Blauw | H5: =COUNTIF(Tatjes!C:C,G5) -> 6 | J5: Zilver | K5: =COUNTIF(Tatjes!B:B,J5)*2+COUNTIF(Tatjes!C:C,J5) -> 21
A6: Ruit | B6: =COUNTIF(Tatjes!A:A,A6) -> 10 | D6: Gras | E6: =COUNTIF(Tatjes!B:B,D6) -> 7 | G6: Zwart | H6: =COUNTIF(Tatjes!C:C,G6) -> 5 | J6: Zwart | K6: =COUNTIF(Tatjes!B:B,J6)*2+COUNTIF(Tatjes!C:C,J6) -> 19
A7: Bijtje | B7: =COUNTIF(Tatjes!A:A,A7) -> 6 | D7: Lila | E7: =COUNTIF(Tatjes!B:B,D7) -> 7 | G7: Lichtgeel | H7: =COUNTIF(Tatjes!C:C,G7) -> 4 | J7: Gras | K7: =COUNTIF(Tatjes!B:B,J7)*2+COUNTIF(Tatjes!C:C,J7) -> 17
A8: Blad | B8: =COUNTIF(Tatjes!A:A,A8) -> 6 | D8: Paars | E8: =COUNTIF(Tatjes!B:B,D8) -> 7 | G8: Fuchsia | H8: =COUNTIF(Tatjes!C:C,G8) -> 3 | J8: Groen | K8: =COUNTIF(Tatjes!B:B,J8)*2+COUNTIF(Tatjes!C:C,J8) -> 16
A9: Klaver3 | B9: =COUNTIF(Tatjes!A:A,A9) -> 4 | D9: Zwart | E9: =COUNTIF(Tatjes!B:B,D9) -> 7 | G9: Gras | H9: =COUNTIF(Tatjes!C:C,G9) -> 3 | J9: Lila | K9: =COUNTIF(Tatjes!B:B,J9)*2+COUNTIF(Tatjes!C:C,J9) -> 16
A10: Lieveheer | B10: =COUNTIF(Tatjes!A:A,A10) -> 3 | D10: Fuchsia | E10: =COUNTIF(Tatjes!B:B,D10) -> 5 | G10: Marine | H10: =COUNTIF(Tatjes!C:C,G10) -> 3 | J10: Aqua | K10: =COUNTIF(Tatjes!B:B,J10)*2+COUNTIF(Tatjes!C:C,J10) -> 15
A11: Rondje | B11: =COUNTIF(Tatjes!A:A,A11) -> 3 | D11: Lichtgeel | E11: =COUNTIF(Tatjes!B:B,D11) -> 5 | G11: Zilver | H11: =COUNTIF(Tatjes!C:C,G11) -> 3 | J11: Lichtgeel | K11: =COUNTIF(Tatjes!B:B,J11)*2+COUNTIF(Tatjes!C:C,J11) -> 14
A12: Wiel | B12: =COUNTIF(Tatjes!A:A,A12) -> 3 | D12: Oranje | E12: =COUNTIF(Tatjes!B:B,D12) -> 5 | G12: Grijs | H12: =COUNTIF(Tatjes!C:C,G12) -> 2 | J12: Fuchsia | K12: =COUNTIF(Tatjes!B:B,J12)*2+COUNTIF(Tatjes!C:C,J12) -> 13
A13: Molentje | B13: =COUNTIF(Tatjes!A:A,A13) -> 1 | D13: Aqua | E13: =COUNTIF(Tatjes!B:B,D13) -> 2 | G13: Lila | H13: =COUNTIF(Tatjes!C:C,G13) -> 2 | J13: Oranje | K13: =COUNTIF(Tatjes!B:B,J13)*2+COUNTIF(Tatjes!C:C,J13) -> 11
D14: Bruin | E14: =COUNTIF(Tatjes!B:B,D14) -> 2 | G14: Oranje | H14: =COUNTIF(Tatjes!C:C,G14) -> 1 | J14: Marine | K14: =COUNTIF(Tatjes!B:B,J14)*2+COUNTIF(Tatjes!C:C,J14) -> 7
A15: TOTAL | B15: =COUNTA(Tatjes!A:A)-1 -> 90 | D15: Marine | E15: =COUNTIF(Tatjes!B:B,D15) -> 2 | G15: Wit | H15: =COUNTIF(Tatjes!C:C,G15) -> 1 | J15: Bruin | K15: =COUNTIF(Tatjes!B:B,J15)*2+COUNTIF(Tatjes!C:C,J15) -> 4
D16: Olijf | E16: =COUNTIF(Tatjes!B:B,D16) -> 2 | G16: Bruin | H16: =COUNTIF(Tatjes!C:C,G16) -> 0 | J16: Olijf | K16: =COUNTIF(Tatjes!B:B,J16)*2+COUNTIF(Tatjes!C:C,J16) -> 4
D17: Rood | E17: =COUNTIF(Tatjes!B:B,D17) -> 2 | G17: Groen | H17: =COUNTIF(Tatjes!C:C,G17) -> 0 | J17: Rood | K17: =COUNTIF(Tatjes!B:B,J17)*2+COUNTIF(Tatjes!C:C,J17) -> 4
D18: Roest | E18: =COUNTIF(Tatjes!B:B,D18) -> 1 | G18: Olijf | H18: =COUNTIF(Tatjes!C:C,G18) -> 0 | J18: Grijs | K18: =COUNTIF(Tatjes!B:B,J18)*2+COUNTIF(Tatjes!C:C,J18) -> 2
D19: Grijs | E19: =COUNTIF(Tatjes!B:B,D19) -> 0 | G19: Roest | H19: =COUNTIF(Tatjes!C:C,G19) -> 0 | J19: Roest | K19: =COUNTIF(Tatjes!B:B,J19)*2+COUNTIF(Tatjes!C:C,J19) -> 2
D20: Wit | E20: =COUNTIF(Tatjes!B:B,D20) -> 0 | G20: Rood | H20: =COUNTIF(Tatjes!C:C,G20) -> 0 | J20: Wit | K20: =COUNTIF(Tatjes!B:B,J20)*2+COUNTIF(Tatjes!C:C,J20) -> 1
